Workbook

Sheet 装箱单
A1: AN-2601 packing list
N3: 日期： | P3: 46244
A5: 材料成份 | B5: 唛头 | C5: 品名 | D5: 款号 | E5: 面料 | F5: 箱号 | G5: 箱数 | H5: 件/箱 | I5: 总件数 | J5: 毛重 | K5: 净重 | L5: 总毛重 | M5: 总净重 | N5: 箱规（CM） | Q5: 立方数 | R5: 备注 | S5: 单价 | T5: 金额
A6: fabric | B6: brand | C6: standard | D6: style no | F6: ctn no. | G6: ctns | H6: pc/ctn | I6: qty | J6: （KGS） | K6: （KGS） | L6: （KGS） | M6: （KGS） | N6: means(cm) | Q6: cm
A7: 100%POLYESTER 针织 起绒 | B7: AMERICAN NICE | C7: 男上衣 | D7: JA26/01HSD | E7: 蚂蚁布 | F7: 1-45 | G7: 45 | H7: 28 | I7: =G7*H7 -> 1260 | J7: 22 | K7: =J7-1.5 -> 20.5 | L7: =G7*J7 -> 990 | M7: =G7*K7 -> 922.5 | N7: 56 | O7: 36 | P7: 62 | Q7: =P7*O7*N7*G7/1000000 -> 5.62464 | R7: MEN JACKET | S7: 6.8 | T7: =S7*I7 -> 8568
C8: 男上衣 | E8: 蚂蚁布 | F8: 46 | G8: 1 | H8: 34 | I8: =G8*H8 -> 34 | J8: 22 | K8: =J8-1.5 -> 20.5 | L8: =G8*J8 -> 22 | M8: =G8*K8 -> 20.5 | N8: 56 | O8: 36 | P8: 62 | Q8: =P8*O8*N8*G8/1000000 -> 0.124992 | R8: MEN JACKET | S8: 6.8 | T8: =S8*I8 -> 231.2
C9: 女上衣 | D9: JA25/01USD PACK A | E9: 摇粒复合布 | F9: 1-32 | G9: 32 | H9: 38 | I9: =G9*H9 -> 1216 | J9: 29.7 | K9: =J9-2 -> 27.7 | L9: =G9*J9 -> 950.4 | M9: =G9*K9 -> 886.4 | N9: 61 | O9: 50 | P9: 82 | Q9: =P9*O9*N9*G9/1000000 -> 8.0032 | R9: LADY JACKET | S9: 6.9 | T9: =S9*I9 -> 8390.4
C10: 女上衣 | E10: 摇粒复合布 | F10: 33-38 | G10: 6 | H10: 38 | I10: =G10*H10 -> 228 | J10: 29.7 | K10: =J10-2 -> 27.7 | L10: =G10*J10 -> 178.2 | M10: =G10*K10 -> 166.2 | N10: 61 | O10: 50 | P10: 82 | Q10: =P10*O10*N10*G10/1000000 -> 1.5006 | R10: LADY JACKET | S10: 6.9 | T10: =S10*I10 -> 1573.2
C11: 女上衣 | D11: JA25/01USD PACK B | E11: 摇粒复合布 | F11: 1-33 | G11: 33 | H11: 38 | I11: =G11*H11 -> 1254 | J11: 29.7 | K11: =J11-2 -> 27.7 | L11: =G11*J11 -> 980.1 | M11: =G11*K11 -> 914.1 | N11: 61 | O11: 50 | P11: 82 | Q11: =P11*O11*N11*G11/1000000 -> 8.2533 | R11: LADY JACKET | S11: 6.9 | T11: =S11*I11 -> 8652.6
C12: 女上衣 | E12: 摇粒复合布 | F12: 34-35 | G12: 4 | H12: 38 | I12: =G12*H12 -> 152 | J12: 29.7 | K12: =J12-2 -> 27.7 | L12: =G12*J12 -> 118.8 | M12: =G12*K12 -> 110.8 | N12: 61 | O12: 50 | P12: 82 | Q12: =P12*O12*N12*G12/1000000 -> 1.0004 | R12: LADY JACKET | S12: 6.9 | T12: =S12*I12 -> 1048.8
C13: 女上衣 | E13: 摇粒复合布 | F13: 36 | G13: 1 | H13: 23 | I13: =G13*H13 -> 23 | J13: 29.7 | K13: =J13-2 -> 27.7 | L13: =G13*J13 -> 29.7 | M13: =G13*K13 -> 27.7 | N13: 61 | O13: 50 | P13: 82 | Q13: =P13*O13*N13*G13/1000000 -> 0.2501 | R13: LADY JACKET | S13: 6.9 | T13: =S13*I13 -> 158.7
C14: 女上衣 | D14: JA25/03USD PACK A | E14: 摇粒复合布 | F14: 1-27 | G14: 27 | H14: 38 | I14: =G14*H14 -> 1026 | J14: 27 | K14: =J14-2 -> 25 | L14: =G14*J14 -> 729 | M14: =G14*K14 -> 675 | N14: 65 | O14: 54 | P14: 68 | Q14: =P14*O14*N14*G14/1000000 -> 6.44436 | R14: LADY JACKET | S14: 6.5 | T14: =S14*I14 -> 6669
C15: 女上衣 | E15: 摇粒复合布 | F15: 28 | G15: 1 | H15: 35 | I15: =G15*H15 -> 35 | J15: 27 | K15: =J15-2 -> 25 | L15: =G15*J15 -> 27 | M15: =G15*K15 -> 25 | N15: 65 | O15: 54 | P15: 68 | Q15: =P15*O15*N15*G15/1000000 -> 0.23868 | R15: LADY JACKET | S15: 6.5 | T15: =S15*I15 -> 227.5
C16: 女上衣 | D16: JA25/03USD PACK B | E16: 摇粒复合布 | F16: 1-28 | G16: 28 | H16: 38 | I16: =G16*H16 -> 1064 | J16: 27 | K16: =J16-2 -> 25 | L16: =G16*J16 -> 756 | M16: =G16*K16 -> 700 | N16: 65 | O16: 54 | P16: 68 | Q16: =P16*O16*N16*G16/1000000 -> 6.68304 | R16: LADY JACKET | S16: 6.5 | T16: =S16*I16 -> 6916
C17: 女童上衣 | D17: JA25/05ISD PACK A | E17: 摇粒复合布 | F17: 1-17 | G17: 17 | H17: 35 | I17: =G17*H17 -> 595 | J17: 22.4 | K17: =J17-2 -> 20.4 | L17: =G17*J17 -> 380.8 | M17: =G17*K17 -> 346.8 | N17: 58 | O17: 50 | P17: 80 | Q17: =P17*O17*N17*G17/1000000 -> 3.944 | R17: GIRL JACKET | S17: 6.4 | T17: =S17*I17 -> 3808
C18: 女童上衣 | E18: 摇粒复合布 | F18: 18 | G18: 1 | H18: 31 | I18: =G18*H18 -> 31 | J18: 22.4 | K18: =J18-2 -> 20.4 | L18: =G18*J18 -> 22.4 | M18: =G18*K18 -> 20.4 | N18: 58 | O18: 50 | P18: 80 | Q18: =P18*O18*N18*G18/1000000 -> 0.232 | R18: GIRL JACKET | S18: 6.4 | T18: =S18*I18 -> 198.4
C19: 女童上衣 | D19: JA25/05ISD PACK B | E19: 摇粒复合布 | F19: 1-18 | G19: 18 | H19: 35 | I19: =G19*H19 -> 630 | J19: 22.4 | K19: =J19-2 -> 20.4 | L19: =G19*J19 -> 403.2 | M19: =G19*K19 -> 367.2 | N19: 58 | O19: 50 | P19: 80 | Q19: =P19*O19*N19*G19/1000000 -> 4.176 | R19: GIRL JACKET | S19: 6.4 | T19: =S19*I19 -> 4032
A20: total: | G20: =SUM(G7:G19) -> 214 | I20: =SUM(I7:I19) -> 7548 | L20: =SUM(L7:L19) -> 5587.6 | M20: =SUM(M7:M19) -> 5182.6 | Q20: =SUM(Q7:Q19) -> 46.475312 | T20: =SUM(T7:T19) -> 50473.8
G22: ='JA26-01HSD'!K10++'JA25-01USD'!K42+'JA25-03USD'!K22+'JA25-05ISD'!K22 -> 214 | I22: ='JA26-01HSD'!M10++'JA25-01USD'!M42+'JA25-03USD'!M22+'JA25-05ISD'!M22 -> 7548 | L22: ='JA26-01HSD'!P10++'JA25-01USD'!P42+'JA25-03USD'!P22+'JA25-05ISD'!P22 -> 5587.6 | M22: ='JA26-01HSD'!Q10++'JA25-01USD'!Q42+'JA25-03USD'!Q22+'JA25-05ISD'!Q22 -> 5182.6 | Q22: ='JA26-01HSD'!U10++'JA25-01USD'!U42+'JA25-03USD'!U22+'JA25-05ISD'!U22 -> 46.475312

Sheet JA26-01HSD
A1: 款号 | B1: 牌子 | C1: 箱号 | D1: 颜色 | E1: 规格 | J1: 件数 | K1: 箱数 | L1: 件/箱 | M1: 总件数 | N1: 毛重 | O1: 净重 | P1: 总毛重 | Q1: 总净重 | R1: 箱规 | U1: 立方 | V1: 备注
A2: style no | B2: brand | C2: carton no | D2: colour | E2: SIZE | J2: quantity (pcs) | K2: ctn | L2: pc/ctn | M2: ctns | N2: G.W | O2: N.W | P2: total gw | Q2: total N.W | R2: total n.w | U2: cbm
E3: CH | F3: M | G3: G | H3: XG | I3: 2XG
A4: JA26/01HSD | B4: AMERICAN NICE | D4: BLACK | E4: 2 | F4: 3 | G4: 3 | H4: 2 | I4: 2 | J4: =SUM(E4:I4) -> 12 | K4: 45 | L4: =J4+J5+J6 -> 28 | M4: =L4*K4 -> 1260 | N4: 22 | O4: =N4-1.5 -> 20.5 | P4: =K4*N4 -> 990 | Q4: =K4*O4 -> 922.5 | R4: 56 | S4: 36 | T4: 62 | U4: =T4*S4*R4*K4/1000000 -> 5.62464
D5: GREEN | E5: 1 | F5: 2 | G5: 2 | H5: 2 | I5: 1 | J5: =SUM(E5:I5) -> 8
D6: BEIGE | E6: 1 | F6: 2 | G6: 2 | H6: 2 | I6: 1 | J6: =SUM(E6:I6) -> 8
D7: BLACK | E7: 2 | F7: 4 | G7: 4 | H7: 1 | I7: 4 | J7: =SUM(E7:I7) -> 15 | K7: 1 | L7: =J7+J8+J9 -> 34 | M7: =L7*K7 -> 34 | N7: 22 | O7: =N7-1.5 -> 20.5 | P7: =K7*N7 -> 22 | Q7: =K7*O7 -> 20.5 | R7: 56 | S7: 36 | T7: 62 | U7: =T7*S7*R7*K7/1000000 -> 0.124992
D8: GREEN | G8: 2 | H8: 2 | J8: =SUM(E8:I8) -> 4
D9: BEIGE | F9: 9 | G9: 4 | H9: 1 | I9: 1 | J9: =SUM(E9:I9) -> 15
A10: TOTAL : | K10: =SUM(K4:K9) -> 46 | M10: =SUM(M4:M9) -> 1294 | P10: =SUM(P4:P9) -> 1012 | Q10: =SUM(Q4:Q9) -> 943 | U10: =SUM(U4:U9) -> 5.749632
A12: 衣服外面 | B12: 衣服里面 | D12: 吊牌（正面） | F12: 吊牌（反面） | J12: 主唛＋号码 | M12: 洗水标 | P12: 胶带（正面） | S12: 胶带（反面） | V12: 纸箱（正唛） | Y12: 纸箱（侧唛）

Sheet JA25-01USD
A1: 款号 | B1: 牌子 | C1: 箱号 | D1: 颜色 | E1: 规格 | J1: 件数 | K1: 箱数 | L1: 件/箱 | M1: 总件数 | N1: 毛重 | O1: 净重 | P1: 总毛重 | Q1: 总净重 | R1: 箱规 | U1: 立方 | V1: 备注
A2: style no | B2: brand | C2: carton no | D2: colour | E2: SIZE | J2: quantity (pcs) | K2: ctn | L2: pc/ctn | M2: ctns | N2: G.W | O2: N.W | P2: total gw | Q2: total N.W | R2: total n.w | U2: cbm
E3: CH | F3: M | G3: G | H3: EG | I3: 2EG
A4: JA25/01USD PACK A | B4: AMERICAN NICE | C4: 1-32 | D4: BLACK | E4: 2 | F4: 3 | G4: 3 | H4: 3 | I4: 2 | J4: =SUM(E4:I4) -> 13 | K4: 32 | L4: =J4+J5+J6+J7+J8+J9 -> 38 | M4: =L4*K4 -> 1216 | N4: 29.7 | O4: =N4-2 -> 27.7 | P4: =K4*N4 -> 950.4 | Q4: =K4*O4 -> 886.4 | R4: 61 | S4: 50 | T4: 82 | U4: =T4*S4*R4*K4/1000000 -> 8.0032
D5: FORMULA ONE | E5: 1 | F5: 1 | G5: 1 | H5: 1 | I5: 1 | J5: =SUM(E5:I5) -> 5
D6: FROSTY GREEN | E6: 1 | F6: 1 | G6: 1 | H6: 1 | I6: 1 | J6: =SUM(E6:I6) -> 5
D7: MAUVE GLOW | E7: 1 | F7: 1 | G7: 1 | H7: 1 | I7: 1 | J7: =SUM(E7:I7) -> 5
D8: WHITECAP GRAY | E8: 1 | F8: 1 | G8: 1 | H8: 1 | I8: 1 | J8: =SUM(E8:I8) -> 5
D9: SAXONY BLUE | E9: 1 | F9: 1 | G9: 1 | H9: 1 | I9: 1 | J9: =SUM(E9:I9) -> 5
C10: 33 | D10: BLACK | E10: 2 | F10: 3 | G10: 3 | H10: 3 | I10: 2 | J10: =SUM(E10:I10) -> 13 | K10: 1 | L10: =J10+J11+J12+J13+J14 -> 38 | M10: =L10*K10 -> 38 | N10: 29.7 | O10: =N10-2 -> 27.7 | P10: =K10*N10 -> 29.7 | Q10: =K10*O10 -> 27.7 | R10: 61 | S10: 50 | T10: 82 | U10: =T10*S10*R10*K10/1000000 -> 0.2501
D11: FROSTY GREEN | E11: 1 | F11: 1 | G11: 1 | H11: 1 | I11: 1 | J11: 5
D12: MAUVE GLOW | E12: 1 | F12: 1 | G12: 1 | H12: 1 | I12: 1 | J12: 5
D13: WHITECAP GRAY | E13: 1 | F13: 1 | G13: 1 | H13: 1 | I13: 1 | J13: 5
D14: SAXONY BLUE | E14: 2 | F14: 2 | G14: 2 | H14: 2 | I14: 2 | J14: =E14+F14+G14+H14+I14 -> 10
C15: 34-35 | D15: BLACK | E15: 2 | F15: 3 | G15: 3 | H15: 3 | I15: 2 | J15: =E15+F15+G15+H15+I15 -> 13 | K15: 2 | L15: =J15+J16+J17+J18 -> 38 | M15: =L15*K15 -> 76 | N15: 29.7 | O15: =N15-2 -> 27.7 | P15: =K15*N15 -> 59.4 | Q15: =K15*O15 -> 55.4 | R15: 61 | S15: 50 | T15: 82 | U15: =T15*S15*R15*K15/1000000 -> 0.5002
D16: FROSTY GREEN | E16: 1 | F16: 1 | G16: 1 | H16: 1 | I16: 1 | J16: =E16+F16+G16+H16+I16 -> 5
D17: WHITECAP GRAY | E17: 2 | F17: 2 | G17: 2 | H17: 2 | I17: 2 | J17: =E17+F17+G17+H17+I17 -> 10
D18: SAXONY BLUE | E18: 2 | F18: 2 | G18: 2 | H18: 2 | I18: 2 | J18: =E18+F18+G18+H18+I18 -> 10
C19: 36-37 | D19: BLACK | E19: 3 | F19: 4 | G19: 4 | H19: 4 | I19: 3 | J19: =E19+F19+G19+H19+I19 -> 18 | K19: 2 | L19: =J19+J20+J21 -> 38 | M19: =L19*K19 -> 76 | N19: 29.7 | O19: =N19-2 -> 27.7 | P19: =K19*N19 -> 59.4 | Q19: =K19*O19 -> 55.4 | R19: 61 | S19: 50 | T19: 82 | U19: =T19*S19*R19*K19/1000000 -> 0.5002
D20: WHITECAP GRAY | E20: 2 | F20: 2 | G20: 2 | H20: 2 | I20: 2 | J20: =E20+F20+G20+H20+I20 -> 10
D21: SAXONY BLUE | E21: 2 | F21: 2 | G21: 2 | H21: 2 | I21: 2 | J21: =E21+F21+G21+H21+I21 -> 10
C22: 38 | D22: BLACK | E22: 4 | F22: 5 | G22: 5 | H22: 5 | I22: 4 | J22: =E22+F22+G22+H22+I22 -> 23 | K22: 1 | L22: =J22+J23+J24 -> 38 | M22: =L22*K22 -> 38 | N22: 29.7 | O22: =N22-2 -> 27.7 | P22: =K22*N22 -> 29.7 | Q22: =K22*O22 -> 27.7 | R22: 61 | S22: 50 | T22: 82 | U22: =T22*S22*R22*K22/1000000 -> 0.2501
D23: WHITECAP GRAY | E23: 2 | F23: 2 | G23: 2 | H23: 2 | I23: 2 | J23: =E23+F23+G23+H23+I23 -> 10
D24: SAXONY BLUE | E24: 1 | F24: 1 | G24: 1 | H24: 1 | I24: 1 | J24: =E24+F24+G24+H24+I24 -> 5
A25: JA25/01USD PACK B | B25: AMERICAN NICE | C25: 1-33 | D25: BLACK | E25: 2 | F25: 3 | G25: 3 | H25: 3 | I25: 2 | J25: =SUM(E25:I25) -> 13 | K25: 33 | L25: =J25+J26+J27+J28+J29+J30 -> 38 | M25: =L25*K25 -> 1254 | N25: 29.7 | O25: =N25-2 -> 27.7 | P25: =K25*N25 -> 980.1 | Q25: =K25*O25 -> 914.1 | R25: 61 | S25: 50 | T25: 82 | U25: =T25*S25*R25*K25/1000000 -> 8.2533
D26: PINE CONE | E26: 1 | F26: 1 | G26: 1 | H26: 1 | I26: 1 | J26: =SUM(E26:I26) -> 5
D27: FROSTY GREEN | E27: 1 | F27: 1 | G27: 1 | H27: 1 | I27: 1 | J27: =SUM(E27:I27) -> 5
D28: SMOKED PEARL | E28: 1 | F28: 1 | G28: 1 | H28: 1 | I28: 1 | J28: =SUM(E28:I28) -> 5
D29: WHITECAP GRAY | E29: 1 | F29: 1 | G29: 1 | H29: 1 | I29: 1 | J29: =SUM(E29:I29) -> 5
D30: FORMULA ONE | E30: 1 | F30: 1 | G30: 1 | H30: 1 | I30: 1 | J30: =SUM(E30:I30) -> 5
C31: 34-35 | D31: BLACK | E31: 3 | F31: 4 | G31: 4 | H31: 4 | I31: 3 | J31: =E31+F31+G31+H31+I31 -> 18 | K31: 2 | L31: =J31+J32+J34+J33 -> 38 | M31: =L31*K31 -> 76 | N31: 29.7 | O31: =N31-2 -> 27.7 | P31: =K31*N31 -> 59.4 | Q31: =K31*O31 -> 55.4 | R31: 61 | S31: 50 | T31: 82 | U31: =T31*S31*R31*K31/1000000 -> 0.5002
D32: PINE CONE | E32: 1 | F32: 1 | G32: 1 | H32: 1 | I32: 1 | J32: =E32+F32+G32+H32+I32 -> 5
D33: FROSTY GREEN | E33: 1 | F33: 1 | G33: 1 | H33: 1 | I33: 1 | J33: =E33+F33+G33+H33+I33 -> 5
D34: WHITECAP GRAY | E34: 2 | F34: 2 | G34: 2 | H34: 2 | I34: 2 | J34: =E34+F34+G34+H34+I34 -> 10
C35: 36 | D35: BLACK | E35: 4 | F35: 5 | G35: 5 | H35: 5 | I35: 4 | J35: =E35+F35+G35+H35+I35 -> 23 | K35: 1 | L35: =J35+J36+J37+J42 -> 38 | M35: =L35*K35 -> 38 | N35: 29.7 | O35: =N35-2 -> 27.7 | P35: =K35*N35 -> 29.7 | Q35: =K35*O35 -> 27.7 | R35: 61 | S35: 50 | T35: 82 | U35: =T35*S35*R35*K35/1000000 -> 0.2501
D36: FROSTY GREEN | E36: 1 | F36: 1 | G36: 1 | H36: 1 | I36: 1 | J36: =E36+F36+G36+H36+I36 -> 5
D37: WHITECAP GRAY | E37: 2 | F37: 2 | G37: 2 | H37: 2 | I37: 2 | J37: =E37+F37+G37+H37+I37 -> 10
C38: 37 | D38: BLACK | E38: 3 | F38: 4 | G38: 4 | H38: 4 | I38: 3 | J38: =E38+F38+G38+H38+I38 -> 18 | K38: 1 | L38: =J38+J39 -> 38 | M38: =L38*K38 -> 38 | N38: 29.7 | O38: =N38-2 -> 27.7 | P38: =K38*N38 -> 29.7 | Q38: =K38*O38 -> 27.7 | R38: 61 | S38: 50 | T38: 82 | U38: =T38*S38*R38*K38/1000000 -> 0.2501
D39: WHITECAP GRAY | E39: 4 | F39: 4 | G39: 4 | H39: 4 | I39: 4 | J39: =E39+F39+G39+H39+I39 -> 20
C40: 38 | D40: BLACK | E40: 1 | F40: 2 | G40: 8 | H40: 6 | I40: 1 | J40: =E40+F40+G40+H40+I40 -> 18 | K40: 1 | L40: =J40+J41+J42+J47 -> 23 | M40: =L40*K40 -> 23 | N40: 29.7 | O40: =N40-2 -> 27.7 | P40: =K40*N40 -> 29.7 | Q40: =K40*O40 -> 27.7 | R40: 61 | S40: 50 | T40: 82 | U40: =T40*S40*R40*K40/1000000 -> 0.2501
...

Sheet JA25-03USD
A1: 款号 | B1: 牌子 | C1: 箱号 | D1: 颜色 | E1: 规格 | J1: 件数 | K1: 箱数 | L1: 件/箱 | M1: 总件数 | N1: 毛重 | O1: 净重 | P1: 总毛重 | Q1: 总净重 | R1: 箱规 | U1: 立方 | V1: 备注
A2: style no | B2: brand | C2: carton no | D2: colour | E2: SIZE | J2: quantity (pcs) | K2: ctn | L2: pc/ctn | M2: ctns | N2: G.W | O2: N.W | P2: total gw | Q2: total N.W | R2: total n.w | U2: cbm
E3: CH | F3: M | G3: G | H3: EG | I3: 2EG
A4: JA25/03USD PACK A | B4: AMERICAN NICE | C4: 1-27 | D4: BLACK /SMOKED PEARL | E4: 2 | F4: 3 | G4: 3 | H4: 3 | I4: 2 | J4: =SUM(E4:I4) -> 13 | K4: 27 | L4: =J4+J5+J8+J6+J7+J9 -> 38 | M4: =L4*K4 -> 1026 | N4: 27 | O4: =N4-2 -> 25 | P4: =K4*N4 -> 729 | Q4: =K4*O4 -> 675 | R4: 65 | S4: 54 | T4: 68 | U4: =T4*S4*R4*K4/1000000 -> 6.44436
D5: FORMULA ONE /SMOKED PEARL | E5: 1 | F5: 1 | G5: 1 | H5: 1 | I5: 1 | J5: =SUM(E5:I5) -> 5
D6: FROSTY GREEN /WHITECAP GRAY | E6: 1 | F6: 1 | G6: 1 | H6: 1 | I6: 1 | J6: =SUM(E6:I6) -> 5
D7: MAUVE GLOW/WHITECAP GRAY | E7: 1 | F7: 1 | G7: 1 | H7: 1 | I7: 1 | J7: =SUM(E7:I7) -> 5
D8: WHITECAP GRAY/FROSTY GREEN | E8: 1 | F8: 1 | G8: 1 | H8: 1 | I8: 1 | J8: =SUM(E8:I8) -> 5
D9: SAXONY BLUE /SMOKED PEARL | E9: 1 | F9: 1 | G9: 1 | H9: 1 | I9: 1 | J9: =E9+F9+G9+H9+I9 -> 5
C10: 28 | D10: BLACK /SMOKED PEARL | E10: 2 | F10: 3 | G10: 3 | H10: 3 | I10: 2 | J10: =E10+F10+G10+H10+I10 -> 13 | K10: 1 | L10: =J10+J11+J12+J13+J14+J15 -> 35 | M10: =L10*K10 -> 35 | N10: 27 | O10: =N10-2 -> 25 | P10: =K10*N10 -> 27 | Q10: =K10*O10 -> 25 | R10: 65 | S10: 54 | T10: 68 | U10: =T10*S10*R10*K10/1000000 -> 0.23868
D11: FORMULA ONE /SMOKED PEARL | E11: 1 | F11: 1 | G11: 1 | H11: 1 | I11: 1 | J11: =E11+F11+G11+H11+I11 -> 5
D12: FROSTY GREEN /WHITECAP GRAY | E12: 1 | F12: 1 | G12: 1 | H12: 1 | I12: 1 | J12: =E12+F12+G12+H12+I12 -> 5
D13: MAUVE GLOW/WHITECAP GRAY | E13: 1 | F13: 1 | G13: 1 | H13: 1 | I13: 1 | J13: =E13+F13+G13+H13+I13 -> 5
D14: WHITECAP GRAY/FROSTY GREEN | E14: 1 | F14: 1 | G14: 1 | H14: 1 | J14: =E14+F14+G14+H14+I14 -> 4
D15: SAXONY BLUE /SMOKED PEARL | E15: 1 | G15: 1 | I15: 1 | J15: =E15+F15+G15+H15+I15 -> 3
A16: JA25/03USD PACK B | B16: AMERICAN NICE | C16: 1-28 | D16: BLACK /SMOKED PEARL | E16: 2 | F16: 3 | G16: 3 | H16: 3 | I16: 2 | J16: =SUM(E16:I16) -> 13 | K16: 28 | L16: =J16+J17+J20+J18+J19+J21 -> 38 | M16: =L16*K16 -> 1064 | N16: 27 | O16: =N16-2 -> 25 | P16: =K16*N16 -> 756 | Q16: =K16*O16 -> 700 | R16: 65 | S16: 54 | T16: 68 | U16: =T16*S16*R16*K16/1000000 -> 6.68304
D17: PINE CONE/WHITECAP GRAY | E17: 1 | F17: 1 | G17: 1 | H17: 1 | I17: 1 | J17: =SUM(E17:I17) -> 5
D18: FROSTY GREEN /WHITECAP GRAY | E18: 1 | F18: 1 | G18: 1 | H18: 1 | I18: 1 | J18: =SUM(E18:I18) -> 5
D19: SMOKED PEARL /BLACK | E19: 1 | F19: 1 | G19: 1 | H19: 1 | I19: 1 | J19: =SUM(E19:I19) -> 5
D20: WHITECAP GRAY /FROSTY GREEN | E20: 1 | F20: 1 | G20: 1 | H20: 1 | I20: 1 | J20: =SUM(E20:I20) -> 5
D21: SAXONY BLUE /SMOKED PEARL | E21: 1 | F21: 1 | G21: 1 | H21: 1 | I21: 1 | J21: =E21+F21+G21+H21+I21 -> 5
A22: TOTAL : | K22: =SUM(K4:K20) -> 56 | M22: =SUM(M4:M20) -> 2125 | P22: =SUM(P4:P20) -> 1512 | Q22: =SUM(Q4:Q20) -> 1400 | U22: =SUM(U4:U20) -> 13.36608
A24: 衣服外面 | B24: 衣服里面 | D24: 吊牌（正面） | F24: 吊牌（反面） | J24: 主唛＋号码 | M24: 洗水标 | P24: 胶带（正面） | S24: 胶带（反面） | V24: 纸箱（正唛） | Y24: 纸箱（侧唛）

Sheet JA25-05ISD
A1: 款号 | B1: 牌子 | C1: 箱号 | D1: 颜色 | E1: 规格 | J1: 件数 | K1: 箱数 | L1: 件/箱 | M1: 总件数 | N1: 毛重 | O1: 净重 | P1: 总毛重 | Q1: 总净重 | R1: 箱规 | U1: 立方 | V1: 备注
A2: style no | B2: brand | C2: carton no | D2: colour | E2: SIZE | J2: quantity (pcs) | K2: ctn | L2: pc/ctn | M2: ctns | N2: G.W | O2: N.W | P2: total gw | Q2: total N.W | R2: total n.w | U2: cbm
E3: 8 | F3: 10 | G3: 12 | H3: 14 | I3: 16
A4: JA25/05ISD PACK A | B4: AMERICAN NICE | C4: 1-17 | D4: BLACK | E4: 2 | F4: 2 | G4: 2 | H4: 2 | I4: 2 | J4: =SUM(E4:I4) -> 10 | K4: 17 | L4: =J4+J5+J8+J6+J7+J9 -> 35 | M4: =L4*K4 -> 595 | N4: 22.4 | O4: =N4-2 -> 20.4 | P4: =K4*N4 -> 380.8 | Q4: =K4*O4 -> 346.8 | R4: 58 | S4: 50 | T4: 80 | U4: =T4*S4*R4*K4/1000000 -> 3.944
D5: FORMULA ONE | E5: 1 | F5: 1 | G5: 1 | H5: 1 | I5: 1 | J5: =SUM(E5:I5) -> 5
D6: FROSTY GREEN | E6: 1 | F6: 1 | G6: 1 | H6: 1 | I6: 1 | J6: =SUM(E6:I6) -> 5
D7: MAUVE GLOW | E7: 1 | F7: 1 | G7: 1 | H7: 1 | I7: 1 | J7: =SUM(E7:I7) -> 5
D8: WHITECAP GRAY | E8: 1 | F8: 1 | G8: 1 | H8: 1 | I8: 1 | J8: =SUM(E8:I8) -> 5
D9: SAXONY BLUE | E9: 1 | F9: 1 | G9: 1 | H9: 1 | I9: 1 | J9: =SUM(E9:I9) -> 5
C10: 18 | D10: BLACK | E10: 2 | F10: 1 | G10: 2 | H10: 2 | I10: 2 | J10: =SUM(E10:I10) -> 9 | K10: 1 | L10: =J10+J11+J14+J12+J13+J15 -> 31 | M10: =L10*K10 -> 31 | N10: 22.4 | O10: =N10-2 -> 20.4 | P10: =K10*N10 -> 22.4 | Q10: =K10*O10 -> 20.4 | R10: 58 | S10: 50 | T10: 80 | U10: =T10*S10*R10*K10/1000000 -> 0.232
D11: FORMULA ONE | F11: 1 | G11: 1 | I11: 1 | J11: =SUM(E11:I11) -> 3
D12: FROSTY GREEN | E12: 1 | F12: 1 | G12: 1 | H12: 1 | I12: 1 | J12: =SUM(E12:I12) -> 5
D13: MAUVE GLOW | E13: 1 | F13: 1 | G13: 1 | H13: 1 | I13: 1 | J13: =SUM(E13:I13) -> 5
D14: WHITECAP GRAY | E14: 1 | F14: 1 | G14: 1 | H14: 1 | I14: 1 | J14: =SUM(E14:I14) -> 5
D15: SAXONY BLUE | E15: 1 | F15: 1 | G15: 1 | I15: 1 | J15: =SUM(E15:I15) -> 4
A16: JA25/05ISD PACK B | C16: 1-18 | D16: BLACK | E16: 2 | F16: 2 | G16: 2 | H16: 2 | I16: 2 | J16: =SUM(E16:I16) -> 10 | K16: 18 | L16: =J16+J17+J20+J18+J19+J21 -> 35 | M16: =L16*K16 -> 630 | N16: 22.4 | O16: =N16-2 -> 20.4 | P16: =K16*N16 -> 403.2 | Q16: =K16*O16 -> 367.2 | R16: 58 | S16: 50 | T16: 80 | U16: =T16*S16*R16*K16/1000000 -> 4.176
D17: PINE CONE | E17: 1 | F17: 1 | G17: 1 | H17: 1 | I17: 1 | J17: =SUM(E17:I17) -> 5
D18: FROSTY GREEN | E18: 1 | F18: 1 | G18: 1 | H18: 1 | I18: 1 | J18: =SUM(E18:I18) -> 5
D19: SMOKED PEARL | E19: 1 | F19: 1 | G19: 1 | H19: 1 | I19: 1 | J19: =SUM(E19:I19) -> 5
D20: WHITECAP GRAY | E20: 1 | F20: 1 | G20: 1 | H20: 1 | I20: 1 | J20: =SUM(E20:I20) -> 5
D21: FORMULA ONE | E21: 1 | F21: 1 | G21: 1 | H21: 1 | I21: 1 | J21: =SUM(E21:I21) -> 5
A22: TOTAL : | K22: =SUM(K4:K21) -> 36 | M22: =SUM(M4:M21) -> 1256 | P22: =SUM(P4:P21) -> 806.4 | Q22: =SUM(Q4:Q21) -> 734.4 | U22: =SUM(U4:U21) -> 8.352
A24: 衣服外面 | B24: 衣服里面 | D24: 吊牌（正面） | F24: 吊牌（反面） | J24: 主唛＋号码 | M24: 洗水标 | P24: 胶带（正面） | S24: 胶带（反面） | V24: 纸箱（正唛） | Y24: 纸箱（侧唛）
